{
 "cells": [
  {
   "cell_type": "code",
   "execution_count": 1,
   "metadata": {},
   "outputs": [
    {
     "name": "stdout",
     "output_type": "stream",
     "text": [
      "Requirement already satisfied: psycopg2 in /Users/ant/anaconda3/envs/dev/lib/python3.10/site-packages (2.9.7)\n",
      "Note: you may need to restart the kernel to use updated packages.\n"
     ]
    }
   ],
   "source": [
    "pip install psycopg2"
   ]
  },
  {
   "cell_type": "code",
   "execution_count": 27,
   "metadata": {},
   "outputs": [
    {
     "ename": "NameError",
     "evalue": "name 'data' is not defined",
     "output_type": "error",
     "traceback": [
      "\u001b[0;31m---------------------------------------------------------------------------\u001b[0m",
      "\u001b[0;31mNameError\u001b[0m                                 Traceback (most recent call last)",
      "Cell \u001b[0;32mIn[27], line 33\u001b[0m\n\u001b[1;32m     30\u001b[0m     writer\u001b[39m.\u001b[39mwriteheader()\n\u001b[1;32m     32\u001b[0m     \u001b[39m# Write the data rows\u001b[39;00m\n\u001b[0;32m---> 33\u001b[0m     \u001b[39mfor\u001b[39;00m row \u001b[39min\u001b[39;00m data:\n\u001b[1;32m     34\u001b[0m         writer\u001b[39m.\u001b[39mwriterow(row)\n\u001b[1;32m     36\u001b[0m \u001b[39mprint\u001b[39m(\u001b[39mf\u001b[39m\u001b[39m'\u001b[39m\u001b[39mData exported to \u001b[39m\u001b[39m{\u001b[39;00mcsv_file\u001b[39m}\u001b[39;00m\u001b[39m'\u001b[39m)\n",
      "\u001b[0;31mNameError\u001b[0m: name 'data' is not defined"
     ]
    }
   ],
   "source": [
    "import csv\n",
    "\n",
    "# Specify the file path for the CSV file\n",
    "csv_file = 'AGI.csv'  # Replace with your desired file name and path\n",
    "\n",
    "# Define the CSV file's header (column names)\n",
    "fieldnames = [\"ZIPCODE\",\n",
    "              \"Total Income per Individual\",\n",
    "              \"Lacking Health Insurance\",\n",
    "              \"Binge Drinking\",\n",
    "              \"High Blood Pressure\",\n",
    "              \"(Non-Skin) Cancer\",\n",
    "              \"Coronary Heart Disease\",\n",
    "              \"Routine Health Checkups\",\n",
    "              \"Currently Smoking\",\n",
    "              \"Dentist Visits\",\n",
    "              \"Depression\",\n",
    "              \"Diabetes\",\n",
    "              \"High Cholesterol\",\n",
    "              \"Chronic Kidney Disease\",\n",
    "              \"No Leisure-Time Physical Activity\",\n",
    "              \"Obesity\",\n",
    "              \"Less than 7 Hours of Sleep,Stroke\"]\n",
    "\n",
    "# Open the CSV file in write mode and write the data\n",
    "with open(csv_file, mode='w', newline='') as file:\n",
    "    writer = csv.DictWriter(file, fieldnames=fieldnames)\n",
    "\n",
    "    # Write the header row\n",
    "    writer.writeheader()\n",
    "\n",
    "    # Write the data rows\n",
    "    for row in data:\n",
    "        writer.writerow(row)\n",
    "\n",
    "print(f'Data exported to {csv_file}')"
   ]
  },
  {
   "cell_type": "code",
   "execution_count": 22,
   "metadata": {},
   "outputs": [],
   "source": [
    "engine = create_engine(\"postgresql+psycopg2://postgres:postgres@localhost:5432/test_db\")\n"
   ]
  },
  {
   "cell_type": "code",
   "execution_count": 19,
   "metadata": {},
   "outputs": [],
   "source": [
    "session = Session(engine)\n"
   ]
  },
  {
   "cell_type": "code",
   "execution_count": 7,
   "metadata": {},
   "outputs": [
    {
     "ename": "OperationalError",
     "evalue": "(psycopg2.OperationalError) FATAL:  database \"test_db\" does not exist\n\n(Background on this error at: https://sqlalche.me/e/14/e3q8)",
     "output_type": "error",
     "traceback": [
      "\u001b[0;31m---------------------------------------------------------------------------\u001b[0m",
      "\u001b[0;31mOperationalError\u001b[0m                          Traceback (most recent call last)",
      "File \u001b[0;32m~/anaconda3/envs/dev/lib/python3.10/site-packages/sqlalchemy/engine/base.py:3280\u001b[0m, in \u001b[0;36mEngine._wrap_pool_connect\u001b[0;34m(self, fn, connection)\u001b[0m\n\u001b[1;32m   3279\u001b[0m \u001b[39mtry\u001b[39;00m:\n\u001b[0;32m-> 3280\u001b[0m     \u001b[39mreturn\u001b[39;00m fn()\n\u001b[1;32m   3281\u001b[0m \u001b[39mexcept\u001b[39;00m dialect\u001b[39m.\u001b[39mdbapi\u001b[39m.\u001b[39mError \u001b[39mas\u001b[39;00m e:\n",
      "File \u001b[0;32m~/anaconda3/envs/dev/lib/python3.10/site-packages/sqlalchemy/pool/base.py:310\u001b[0m, in \u001b[0;36mPool.connect\u001b[0;34m(self)\u001b[0m\n\u001b[1;32m    303\u001b[0m \u001b[39m\"\"\"Return a DBAPI connection from the pool.\u001b[39;00m\n\u001b[1;32m    304\u001b[0m \n\u001b[1;32m    305\u001b[0m \u001b[39mThe connection is instrumented such that when its\u001b[39;00m\n\u001b[0;32m   (...)\u001b[0m\n\u001b[1;32m    308\u001b[0m \n\u001b[1;32m    309\u001b[0m \u001b[39m\"\"\"\u001b[39;00m\n\u001b[0;32m--> 310\u001b[0m \u001b[39mreturn\u001b[39;00m _ConnectionFairy\u001b[39m.\u001b[39;49m_checkout(\u001b[39mself\u001b[39;49m)\n",
      "File \u001b[0;32m~/anaconda3/envs/dev/lib/python3.10/site-packages/sqlalchemy/pool/base.py:868\u001b[0m, in \u001b[0;36m_ConnectionFairy._checkout\u001b[0;34m(cls, pool, threadconns, fairy)\u001b[0m\n\u001b[1;32m    867\u001b[0m \u001b[39mif\u001b[39;00m \u001b[39mnot\u001b[39;00m fairy:\n\u001b[0;32m--> 868\u001b[0m     fairy \u001b[39m=\u001b[39m _ConnectionRecord\u001b[39m.\u001b[39;49mcheckout(pool)\n\u001b[1;32m    870\u001b[0m     fairy\u001b[39m.\u001b[39m_pool \u001b[39m=\u001b[39m pool\n",
      "File \u001b[0;32m~/anaconda3/envs/dev/lib/python3.10/site-packages/sqlalchemy/pool/base.py:476\u001b[0m, in \u001b[0;36m_ConnectionRecord.checkout\u001b[0;34m(cls, pool)\u001b[0m\n\u001b[1;32m    474\u001b[0m \u001b[39m@classmethod\u001b[39m\n\u001b[1;32m    475\u001b[0m \u001b[39mdef\u001b[39;00m \u001b[39mcheckout\u001b[39m(\u001b[39mcls\u001b[39m, pool):\n\u001b[0;32m--> 476\u001b[0m     rec \u001b[39m=\u001b[39m pool\u001b[39m.\u001b[39;49m_do_get()\n\u001b[1;32m    477\u001b[0m     \u001b[39mtry\u001b[39;00m:\n",
      "File \u001b[0;32m~/anaconda3/envs/dev/lib/python3.10/site-packages/sqlalchemy/pool/impl.py:145\u001b[0m, in \u001b[0;36mQueuePool._do_get\u001b[0;34m(self)\u001b[0m\n\u001b[1;32m    144\u001b[0m \u001b[39mexcept\u001b[39;00m:\n\u001b[0;32m--> 145\u001b[0m     \u001b[39mwith\u001b[39;00m util\u001b[39m.\u001b[39msafe_reraise():\n\u001b[1;32m    146\u001b[0m         \u001b[39mself\u001b[39m\u001b[39m.\u001b[39m_dec_overflow()\n",
      "File \u001b[0;32m~/anaconda3/envs/dev/lib/python3.10/site-packages/sqlalchemy/util/langhelpers.py:70\u001b[0m, in \u001b[0;36msafe_reraise.__exit__\u001b[0;34m(self, type_, value, traceback)\u001b[0m\n\u001b[1;32m     69\u001b[0m     \u001b[39mif\u001b[39;00m \u001b[39mnot\u001b[39;00m \u001b[39mself\u001b[39m\u001b[39m.\u001b[39mwarn_only:\n\u001b[0;32m---> 70\u001b[0m         compat\u001b[39m.\u001b[39;49mraise_(\n\u001b[1;32m     71\u001b[0m             exc_value,\n\u001b[1;32m     72\u001b[0m             with_traceback\u001b[39m=\u001b[39;49mexc_tb,\n\u001b[1;32m     73\u001b[0m         )\n\u001b[1;32m     74\u001b[0m \u001b[39melse\u001b[39;00m:\n",
      "File \u001b[0;32m~/anaconda3/envs/dev/lib/python3.10/site-packages/sqlalchemy/util/compat.py:208\u001b[0m, in \u001b[0;36mraise_\u001b[0;34m(***failed resolving arguments***)\u001b[0m\n\u001b[1;32m    207\u001b[0m \u001b[39mtry\u001b[39;00m:\n\u001b[0;32m--> 208\u001b[0m     \u001b[39mraise\u001b[39;00m exception\n\u001b[1;32m    209\u001b[0m \u001b[39mfinally\u001b[39;00m:\n\u001b[1;32m    210\u001b[0m     \u001b[39m# credit to\u001b[39;00m\n\u001b[1;32m    211\u001b[0m     \u001b[39m# https://cosmicpercolator.com/2016/01/13/exception-leaks-in-python-2-and-3/\u001b[39;00m\n\u001b[1;32m    212\u001b[0m     \u001b[39m# as the __traceback__ object creates a cycle\u001b[39;00m\n",
      "File \u001b[0;32m~/anaconda3/envs/dev/lib/python3.10/site-packages/sqlalchemy/pool/impl.py:143\u001b[0m, in \u001b[0;36mQueuePool._do_get\u001b[0;34m(self)\u001b[0m\n\u001b[1;32m    142\u001b[0m \u001b[39mtry\u001b[39;00m:\n\u001b[0;32m--> 143\u001b[0m     \u001b[39mreturn\u001b[39;00m \u001b[39mself\u001b[39;49m\u001b[39m.\u001b[39;49m_create_connection()\n\u001b[1;32m    144\u001b[0m \u001b[39mexcept\u001b[39;00m:\n",
      "File \u001b[0;32m~/anaconda3/envs/dev/lib/python3.10/site-packages/sqlalchemy/pool/base.py:256\u001b[0m, in \u001b[0;36mPool._create_connection\u001b[0;34m(self)\u001b[0m\n\u001b[1;32m    254\u001b[0m \u001b[39m\"\"\"Called by subclasses to create a new ConnectionRecord.\"\"\"\u001b[39;00m\n\u001b[0;32m--> 256\u001b[0m \u001b[39mreturn\u001b[39;00m _ConnectionRecord(\u001b[39mself\u001b[39;49m)\n",
      "File \u001b[0;32m~/anaconda3/envs/dev/lib/python3.10/site-packages/sqlalchemy/pool/base.py:371\u001b[0m, in \u001b[0;36m_ConnectionRecord.__init__\u001b[0;34m(self, pool, connect)\u001b[0m\n\u001b[1;32m    370\u001b[0m \u001b[39mif\u001b[39;00m connect:\n\u001b[0;32m--> 371\u001b[0m     \u001b[39mself\u001b[39;49m\u001b[39m.\u001b[39;49m__connect()\n\u001b[1;32m    372\u001b[0m \u001b[39mself\u001b[39m\u001b[39m.\u001b[39mfinalize_callback \u001b[39m=\u001b[39m deque()\n",
      "File \u001b[0;32m~/anaconda3/envs/dev/lib/python3.10/site-packages/sqlalchemy/pool/base.py:665\u001b[0m, in \u001b[0;36m_ConnectionRecord.__connect\u001b[0;34m(self)\u001b[0m\n\u001b[1;32m    664\u001b[0m \u001b[39mexcept\u001b[39;00m \u001b[39mException\u001b[39;00m \u001b[39mas\u001b[39;00m e:\n\u001b[0;32m--> 665\u001b[0m     \u001b[39mwith\u001b[39;00m util\u001b[39m.\u001b[39msafe_reraise():\n\u001b[1;32m    666\u001b[0m         pool\u001b[39m.\u001b[39mlogger\u001b[39m.\u001b[39mdebug(\u001b[39m\"\u001b[39m\u001b[39mError on connect(): \u001b[39m\u001b[39m%s\u001b[39;00m\u001b[39m\"\u001b[39m, e)\n",
      "File \u001b[0;32m~/anaconda3/envs/dev/lib/python3.10/site-packages/sqlalchemy/util/langhelpers.py:70\u001b[0m, in \u001b[0;36msafe_reraise.__exit__\u001b[0;34m(self, type_, value, traceback)\u001b[0m\n\u001b[1;32m     69\u001b[0m     \u001b[39mif\u001b[39;00m \u001b[39mnot\u001b[39;00m \u001b[39mself\u001b[39m\u001b[39m.\u001b[39mwarn_only:\n\u001b[0;32m---> 70\u001b[0m         compat\u001b[39m.\u001b[39;49mraise_(\n\u001b[1;32m     71\u001b[0m             exc_value,\n\u001b[1;32m     72\u001b[0m             with_traceback\u001b[39m=\u001b[39;49mexc_tb,\n\u001b[1;32m     73\u001b[0m         )\n\u001b[1;32m     74\u001b[0m \u001b[39melse\u001b[39;00m:\n",
      "File \u001b[0;32m~/anaconda3/envs/dev/lib/python3.10/site-packages/sqlalchemy/util/compat.py:208\u001b[0m, in \u001b[0;36mraise_\u001b[0;34m(***failed resolving arguments***)\u001b[0m\n\u001b[1;32m    207\u001b[0m \u001b[39mtry\u001b[39;00m:\n\u001b[0;32m--> 208\u001b[0m     \u001b[39mraise\u001b[39;00m exception\n\u001b[1;32m    209\u001b[0m \u001b[39mfinally\u001b[39;00m:\n\u001b[1;32m    210\u001b[0m     \u001b[39m# credit to\u001b[39;00m\n\u001b[1;32m    211\u001b[0m     \u001b[39m# https://cosmicpercolator.com/2016/01/13/exception-leaks-in-python-2-and-3/\u001b[39;00m\n\u001b[1;32m    212\u001b[0m     \u001b[39m# as the __traceback__ object creates a cycle\u001b[39;00m\n",
      "File \u001b[0;32m~/anaconda3/envs/dev/lib/python3.10/site-packages/sqlalchemy/pool/base.py:661\u001b[0m, in \u001b[0;36m_ConnectionRecord.__connect\u001b[0;34m(self)\u001b[0m\n\u001b[1;32m    660\u001b[0m \u001b[39mself\u001b[39m\u001b[39m.\u001b[39mstarttime \u001b[39m=\u001b[39m time\u001b[39m.\u001b[39mtime()\n\u001b[0;32m--> 661\u001b[0m \u001b[39mself\u001b[39m\u001b[39m.\u001b[39mdbapi_connection \u001b[39m=\u001b[39m connection \u001b[39m=\u001b[39m pool\u001b[39m.\u001b[39;49m_invoke_creator(\u001b[39mself\u001b[39;49m)\n\u001b[1;32m    662\u001b[0m pool\u001b[39m.\u001b[39mlogger\u001b[39m.\u001b[39mdebug(\u001b[39m\"\u001b[39m\u001b[39mCreated new connection \u001b[39m\u001b[39m%r\u001b[39;00m\u001b[39m\"\u001b[39m, connection)\n",
      "File \u001b[0;32m~/anaconda3/envs/dev/lib/python3.10/site-packages/sqlalchemy/engine/create.py:590\u001b[0m, in \u001b[0;36mcreate_engine.<locals>.connect\u001b[0;34m(connection_record)\u001b[0m\n\u001b[1;32m    589\u001b[0m             \u001b[39mreturn\u001b[39;00m connection\n\u001b[0;32m--> 590\u001b[0m \u001b[39mreturn\u001b[39;00m dialect\u001b[39m.\u001b[39;49mconnect(\u001b[39m*\u001b[39;49mcargs, \u001b[39m*\u001b[39;49m\u001b[39m*\u001b[39;49mcparams)\n",
      "File \u001b[0;32m~/anaconda3/envs/dev/lib/python3.10/site-packages/sqlalchemy/engine/default.py:597\u001b[0m, in \u001b[0;36mDefaultDialect.connect\u001b[0;34m(self, *cargs, **cparams)\u001b[0m\n\u001b[1;32m    595\u001b[0m \u001b[39mdef\u001b[39;00m \u001b[39mconnect\u001b[39m(\u001b[39mself\u001b[39m, \u001b[39m*\u001b[39mcargs, \u001b[39m*\u001b[39m\u001b[39m*\u001b[39mcparams):\n\u001b[1;32m    596\u001b[0m     \u001b[39m# inherits the docstring from interfaces.Dialect.connect\u001b[39;00m\n\u001b[0;32m--> 597\u001b[0m     \u001b[39mreturn\u001b[39;00m \u001b[39mself\u001b[39;49m\u001b[39m.\u001b[39;49mdbapi\u001b[39m.\u001b[39;49mconnect(\u001b[39m*\u001b[39;49mcargs, \u001b[39m*\u001b[39;49m\u001b[39m*\u001b[39;49mcparams)\n",
      "File \u001b[0;32m~/anaconda3/envs/dev/lib/python3.10/site-packages/psycopg2/__init__.py:122\u001b[0m, in \u001b[0;36mconnect\u001b[0;34m(dsn, connection_factory, cursor_factory, **kwargs)\u001b[0m\n\u001b[1;32m    121\u001b[0m dsn \u001b[39m=\u001b[39m _ext\u001b[39m.\u001b[39mmake_dsn(dsn, \u001b[39m*\u001b[39m\u001b[39m*\u001b[39mkwargs)\n\u001b[0;32m--> 122\u001b[0m conn \u001b[39m=\u001b[39m _connect(dsn, connection_factory\u001b[39m=\u001b[39;49mconnection_factory, \u001b[39m*\u001b[39;49m\u001b[39m*\u001b[39;49mkwasync)\n\u001b[1;32m    123\u001b[0m \u001b[39mif\u001b[39;00m cursor_factory \u001b[39mis\u001b[39;00m \u001b[39mnot\u001b[39;00m \u001b[39mNone\u001b[39;00m:\n",
      "\u001b[0;31mOperationalError\u001b[0m: FATAL:  database \"test_db\" does not exist\n",
      "\nThe above exception was the direct cause of the following exception:\n",
      "\u001b[0;31mOperationalError\u001b[0m                          Traceback (most recent call last)",
      "Cell \u001b[0;32mIn[7], line 3\u001b[0m\n\u001b[1;32m      1\u001b[0m \u001b[39m# Reflect Database into ORM classes\u001b[39;00m\n\u001b[1;32m      2\u001b[0m Base \u001b[39m=\u001b[39m automap_base()\n\u001b[0;32m----> 3\u001b[0m Base\u001b[39m.\u001b[39;49mprepare(autoload_with\u001b[39m=\u001b[39;49mengine)\n\u001b[1;32m      4\u001b[0m Base\u001b[39m.\u001b[39mclasses\u001b[39m.\u001b[39mkeys()\n",
      "File \u001b[0;32m<string>:2\u001b[0m, in \u001b[0;36mprepare\u001b[0;34m(cls, autoload_with, engine, reflect, schema, classname_for_table, collection_class, name_for_scalar_relationship, name_for_collection_relationship, generate_relationship, reflection_options)\u001b[0m\n",
      "File \u001b[0;32m~/anaconda3/envs/dev/lib/python3.10/site-packages/sqlalchemy/util/deprecations.py:309\u001b[0m, in \u001b[0;36mdeprecated_params.<locals>.decorate.<locals>.warned\u001b[0;34m(fn, *args, **kwargs)\u001b[0m\n\u001b[1;32m    302\u001b[0m     \u001b[39mif\u001b[39;00m m \u001b[39min\u001b[39;00m kwargs:\n\u001b[1;32m    303\u001b[0m         _warn_with_version(\n\u001b[1;32m    304\u001b[0m             messages[m],\n\u001b[1;32m    305\u001b[0m             versions[m],\n\u001b[1;32m    306\u001b[0m             version_warnings[m],\n\u001b[1;32m    307\u001b[0m             stacklevel\u001b[39m=\u001b[39m\u001b[39m3\u001b[39m,\n\u001b[1;32m    308\u001b[0m         )\n\u001b[0;32m--> 309\u001b[0m \u001b[39mreturn\u001b[39;00m fn(\u001b[39m*\u001b[39;49margs, \u001b[39m*\u001b[39;49m\u001b[39m*\u001b[39;49mkwargs)\n",
      "File \u001b[0;32m~/anaconda3/envs/dev/lib/python3.10/site-packages/sqlalchemy/ext/automap.py:882\u001b[0m, in \u001b[0;36mAutomapBase.prepare\u001b[0;34m(cls, autoload_with, engine, reflect, schema, classname_for_table, collection_class, name_for_scalar_relationship, name_for_collection_relationship, generate_relationship, reflection_options)\u001b[0m\n\u001b[1;32m    880\u001b[0m     \u001b[39mif\u001b[39;00m reflection_options:\n\u001b[1;32m    881\u001b[0m         opts\u001b[39m.\u001b[39mupdate(reflection_options)\n\u001b[0;32m--> 882\u001b[0m     \u001b[39mcls\u001b[39;49m\u001b[39m.\u001b[39;49mmetadata\u001b[39m.\u001b[39;49mreflect(autoload_with, \u001b[39m*\u001b[39;49m\u001b[39m*\u001b[39;49mopts)\n\u001b[1;32m    884\u001b[0m \u001b[39mwith\u001b[39;00m _CONFIGURE_MUTEX:\n\u001b[1;32m    885\u001b[0m     table_to_map_config \u001b[39m=\u001b[39m \u001b[39mdict\u001b[39m(\n\u001b[1;32m    886\u001b[0m         (m\u001b[39m.\u001b[39mlocal_table, m)\n\u001b[1;32m    887\u001b[0m         \u001b[39mfor\u001b[39;00m m \u001b[39min\u001b[39;00m _DeferredMapperConfig\u001b[39m.\u001b[39mclasses_for_base(\n\u001b[1;32m    888\u001b[0m             \u001b[39mcls\u001b[39m, sort\u001b[39m=\u001b[39m\u001b[39mFalse\u001b[39;00m\n\u001b[1;32m    889\u001b[0m         )\n\u001b[1;32m    890\u001b[0m     )\n",
      "File \u001b[0;32m~/anaconda3/envs/dev/lib/python3.10/site-packages/sqlalchemy/sql/schema.py:4828\u001b[0m, in \u001b[0;36mMetaData.reflect\u001b[0;34m(self, bind, schema, views, only, extend_existing, autoload_replace, resolve_fks, **dialect_kwargs)\u001b[0m\n\u001b[1;32m   4825\u001b[0m \u001b[39mif\u001b[39;00m bind \u001b[39mis\u001b[39;00m \u001b[39mNone\u001b[39;00m:\n\u001b[1;32m   4826\u001b[0m     bind \u001b[39m=\u001b[39m _bind_or_error(\u001b[39mself\u001b[39m)\n\u001b[0;32m-> 4828\u001b[0m \u001b[39mwith\u001b[39;00m inspection\u001b[39m.\u001b[39;49minspect(bind)\u001b[39m.\u001b[39m_inspection_context() \u001b[39mas\u001b[39;00m insp:\n\u001b[1;32m   4829\u001b[0m     reflect_opts \u001b[39m=\u001b[39m {\n\u001b[1;32m   4830\u001b[0m         \u001b[39m\"\u001b[39m\u001b[39mautoload_with\u001b[39m\u001b[39m\"\u001b[39m: insp,\n\u001b[1;32m   4831\u001b[0m         \u001b[39m\"\u001b[39m\u001b[39mextend_existing\u001b[39m\u001b[39m\"\u001b[39m: extend_existing,\n\u001b[0;32m   (...)\u001b[0m\n\u001b[1;32m   4834\u001b[0m         \u001b[39m\"\u001b[39m\u001b[39m_extend_on\u001b[39m\u001b[39m\"\u001b[39m: \u001b[39mset\u001b[39m(),\n\u001b[1;32m   4835\u001b[0m     }\n\u001b[1;32m   4837\u001b[0m     reflect_opts\u001b[39m.\u001b[39mupdate(dialect_kwargs)\n",
      "File \u001b[0;32m~/anaconda3/envs/dev/lib/python3.10/site-packages/sqlalchemy/inspection.py:64\u001b[0m, in \u001b[0;36minspect\u001b[0;34m(subject, raiseerr)\u001b[0m\n\u001b[1;32m     62\u001b[0m \u001b[39mif\u001b[39;00m reg \u001b[39mis\u001b[39;00m \u001b[39mTrue\u001b[39;00m:\n\u001b[1;32m     63\u001b[0m     \u001b[39mreturn\u001b[39;00m subject\n\u001b[0;32m---> 64\u001b[0m ret \u001b[39m=\u001b[39m reg(subject)\n\u001b[1;32m     65\u001b[0m \u001b[39mif\u001b[39;00m ret \u001b[39mis\u001b[39;00m \u001b[39mnot\u001b[39;00m \u001b[39mNone\u001b[39;00m:\n\u001b[1;32m     66\u001b[0m     \u001b[39mbreak\u001b[39;00m\n",
      "File \u001b[0;32m~/anaconda3/envs/dev/lib/python3.10/site-packages/sqlalchemy/engine/reflection.py:182\u001b[0m, in \u001b[0;36mInspector._engine_insp\u001b[0;34m(bind)\u001b[0m\n\u001b[1;32m    180\u001b[0m \u001b[39m@inspection\u001b[39m\u001b[39m.\u001b[39m_inspects(Engine)\n\u001b[1;32m    181\u001b[0m \u001b[39mdef\u001b[39;00m \u001b[39m_engine_insp\u001b[39m(bind):\n\u001b[0;32m--> 182\u001b[0m     \u001b[39mreturn\u001b[39;00m Inspector\u001b[39m.\u001b[39;49m_construct(Inspector\u001b[39m.\u001b[39;49m_init_engine, bind)\n",
      "File \u001b[0;32m~/anaconda3/envs/dev/lib/python3.10/site-packages/sqlalchemy/engine/reflection.py:117\u001b[0m, in \u001b[0;36mInspector._construct\u001b[0;34m(cls, init, bind)\u001b[0m\n\u001b[1;32m    114\u001b[0m     \u001b[39mcls\u001b[39m \u001b[39m=\u001b[39m bind\u001b[39m.\u001b[39mdialect\u001b[39m.\u001b[39minspector\n\u001b[1;32m    116\u001b[0m \u001b[39mself\u001b[39m \u001b[39m=\u001b[39m \u001b[39mcls\u001b[39m\u001b[39m.\u001b[39m\u001b[39m__new__\u001b[39m(\u001b[39mcls\u001b[39m)\n\u001b[0;32m--> 117\u001b[0m init(\u001b[39mself\u001b[39;49m, bind)\n\u001b[1;32m    118\u001b[0m \u001b[39mreturn\u001b[39;00m \u001b[39mself\u001b[39m\n",
      "File \u001b[0;32m~/anaconda3/envs/dev/lib/python3.10/site-packages/sqlalchemy/engine/reflection.py:128\u001b[0m, in \u001b[0;36mInspector._init_engine\u001b[0;34m(self, engine)\u001b[0m\n\u001b[1;32m    126\u001b[0m \u001b[39mdef\u001b[39;00m \u001b[39m_init_engine\u001b[39m(\u001b[39mself\u001b[39m, engine):\n\u001b[1;32m    127\u001b[0m     \u001b[39mself\u001b[39m\u001b[39m.\u001b[39mbind \u001b[39m=\u001b[39m \u001b[39mself\u001b[39m\u001b[39m.\u001b[39mengine \u001b[39m=\u001b[39m engine\n\u001b[0;32m--> 128\u001b[0m     engine\u001b[39m.\u001b[39;49mconnect()\u001b[39m.\u001b[39mclose()\n\u001b[1;32m    129\u001b[0m     \u001b[39mself\u001b[39m\u001b[39m.\u001b[39m_op_context_requires_connect \u001b[39m=\u001b[39m \u001b[39mTrue\u001b[39;00m\n\u001b[1;32m    130\u001b[0m     \u001b[39mself\u001b[39m\u001b[39m.\u001b[39mdialect \u001b[39m=\u001b[39m \u001b[39mself\u001b[39m\u001b[39m.\u001b[39mengine\u001b[39m.\u001b[39mdialect\n",
      "File \u001b[0;32m~/anaconda3/envs/dev/lib/python3.10/site-packages/sqlalchemy/engine/base.py:3234\u001b[0m, in \u001b[0;36mEngine.connect\u001b[0;34m(self, close_with_result)\u001b[0m\n\u001b[1;32m   3219\u001b[0m \u001b[39mdef\u001b[39;00m \u001b[39mconnect\u001b[39m(\u001b[39mself\u001b[39m, close_with_result\u001b[39m=\u001b[39m\u001b[39mFalse\u001b[39;00m):\n\u001b[1;32m   3220\u001b[0m     \u001b[39m\"\"\"Return a new :class:`_engine.Connection` object.\u001b[39;00m\n\u001b[1;32m   3221\u001b[0m \n\u001b[1;32m   3222\u001b[0m \u001b[39m    The :class:`_engine.Connection` object is a facade that uses a DBAPI\u001b[39;00m\n\u001b[0;32m   (...)\u001b[0m\n\u001b[1;32m   3231\u001b[0m \n\u001b[1;32m   3232\u001b[0m \u001b[39m    \"\"\"\u001b[39;00m\n\u001b[0;32m-> 3234\u001b[0m     \u001b[39mreturn\u001b[39;00m \u001b[39mself\u001b[39;49m\u001b[39m.\u001b[39;49m_connection_cls(\u001b[39mself\u001b[39;49m, close_with_result\u001b[39m=\u001b[39;49mclose_with_result)\n",
      "File \u001b[0;32m~/anaconda3/envs/dev/lib/python3.10/site-packages/sqlalchemy/engine/base.py:96\u001b[0m, in \u001b[0;36mConnection.__init__\u001b[0;34m(self, engine, connection, close_with_result, _branch_from, _execution_options, _dispatch, _has_events, _allow_revalidate)\u001b[0m\n\u001b[1;32m     91\u001b[0m     \u001b[39mself\u001b[39m\u001b[39m.\u001b[39m_has_events \u001b[39m=\u001b[39m _branch_from\u001b[39m.\u001b[39m_has_events\n\u001b[1;32m     92\u001b[0m \u001b[39melse\u001b[39;00m:\n\u001b[1;32m     93\u001b[0m     \u001b[39mself\u001b[39m\u001b[39m.\u001b[39m_dbapi_connection \u001b[39m=\u001b[39m (\n\u001b[1;32m     94\u001b[0m         connection\n\u001b[1;32m     95\u001b[0m         \u001b[39mif\u001b[39;00m connection \u001b[39mis\u001b[39;00m \u001b[39mnot\u001b[39;00m \u001b[39mNone\u001b[39;00m\n\u001b[0;32m---> 96\u001b[0m         \u001b[39melse\u001b[39;00m engine\u001b[39m.\u001b[39;49mraw_connection()\n\u001b[1;32m     97\u001b[0m     )\n\u001b[1;32m     99\u001b[0m     \u001b[39mself\u001b[39m\u001b[39m.\u001b[39m_transaction \u001b[39m=\u001b[39m \u001b[39mself\u001b[39m\u001b[39m.\u001b[39m_nested_transaction \u001b[39m=\u001b[39m \u001b[39mNone\u001b[39;00m\n\u001b[1;32m    100\u001b[0m     \u001b[39mself\u001b[39m\u001b[39m.\u001b[39m__savepoint_seq \u001b[39m=\u001b[39m \u001b[39m0\u001b[39m\n",
      "File \u001b[0;32m~/anaconda3/envs/dev/lib/python3.10/site-packages/sqlalchemy/engine/base.py:3313\u001b[0m, in \u001b[0;36mEngine.raw_connection\u001b[0;34m(self, _connection)\u001b[0m\n\u001b[1;32m   3291\u001b[0m \u001b[39mdef\u001b[39;00m \u001b[39mraw_connection\u001b[39m(\u001b[39mself\u001b[39m, _connection\u001b[39m=\u001b[39m\u001b[39mNone\u001b[39;00m):\n\u001b[1;32m   3292\u001b[0m     \u001b[39m\"\"\"Return a \"raw\" DBAPI connection from the connection pool.\u001b[39;00m\n\u001b[1;32m   3293\u001b[0m \n\u001b[1;32m   3294\u001b[0m \u001b[39m    The returned object is a proxied version of the DBAPI\u001b[39;00m\n\u001b[0;32m   (...)\u001b[0m\n\u001b[1;32m   3311\u001b[0m \n\u001b[1;32m   3312\u001b[0m \u001b[39m    \"\"\"\u001b[39;00m\n\u001b[0;32m-> 3313\u001b[0m     \u001b[39mreturn\u001b[39;00m \u001b[39mself\u001b[39;49m\u001b[39m.\u001b[39;49m_wrap_pool_connect(\u001b[39mself\u001b[39;49m\u001b[39m.\u001b[39;49mpool\u001b[39m.\u001b[39;49mconnect, _connection)\n",
      "File \u001b[0;32m~/anaconda3/envs/dev/lib/python3.10/site-packages/sqlalchemy/engine/base.py:3283\u001b[0m, in \u001b[0;36mEngine._wrap_pool_connect\u001b[0;34m(self, fn, connection)\u001b[0m\n\u001b[1;32m   3281\u001b[0m \u001b[39mexcept\u001b[39;00m dialect\u001b[39m.\u001b[39mdbapi\u001b[39m.\u001b[39mError \u001b[39mas\u001b[39;00m e:\n\u001b[1;32m   3282\u001b[0m     \u001b[39mif\u001b[39;00m connection \u001b[39mis\u001b[39;00m \u001b[39mNone\u001b[39;00m:\n\u001b[0;32m-> 3283\u001b[0m         Connection\u001b[39m.\u001b[39;49m_handle_dbapi_exception_noconnection(\n\u001b[1;32m   3284\u001b[0m             e, dialect, \u001b[39mself\u001b[39;49m\n\u001b[1;32m   3285\u001b[0m         )\n\u001b[1;32m   3286\u001b[0m     \u001b[39melse\u001b[39;00m:\n\u001b[1;32m   3287\u001b[0m         util\u001b[39m.\u001b[39mraise_(\n\u001b[1;32m   3288\u001b[0m             sys\u001b[39m.\u001b[39mexc_info()[\u001b[39m1\u001b[39m], with_traceback\u001b[39m=\u001b[39msys\u001b[39m.\u001b[39mexc_info()[\u001b[39m2\u001b[39m]\n\u001b[1;32m   3289\u001b[0m         )\n",
      "File \u001b[0;32m~/anaconda3/envs/dev/lib/python3.10/site-packages/sqlalchemy/engine/base.py:2117\u001b[0m, in \u001b[0;36mConnection._handle_dbapi_exception_noconnection\u001b[0;34m(cls, e, dialect, engine)\u001b[0m\n\u001b[1;32m   2115\u001b[0m     util\u001b[39m.\u001b[39mraise_(newraise, with_traceback\u001b[39m=\u001b[39mexc_info[\u001b[39m2\u001b[39m], from_\u001b[39m=\u001b[39me)\n\u001b[1;32m   2116\u001b[0m \u001b[39melif\u001b[39;00m should_wrap:\n\u001b[0;32m-> 2117\u001b[0m     util\u001b[39m.\u001b[39;49mraise_(\n\u001b[1;32m   2118\u001b[0m         sqlalchemy_exception, with_traceback\u001b[39m=\u001b[39;49mexc_info[\u001b[39m2\u001b[39;49m], from_\u001b[39m=\u001b[39;49me\n\u001b[1;32m   2119\u001b[0m     )\n\u001b[1;32m   2120\u001b[0m \u001b[39melse\u001b[39;00m:\n\u001b[1;32m   2121\u001b[0m     util\u001b[39m.\u001b[39mraise_(exc_info[\u001b[39m1\u001b[39m], with_traceback\u001b[39m=\u001b[39mexc_info[\u001b[39m2\u001b[39m])\n",
      "File \u001b[0;32m~/anaconda3/envs/dev/lib/python3.10/site-packages/sqlalchemy/util/compat.py:208\u001b[0m, in \u001b[0;36mraise_\u001b[0;34m(***failed resolving arguments***)\u001b[0m\n\u001b[1;32m    205\u001b[0m     exception\u001b[39m.\u001b[39m__cause__ \u001b[39m=\u001b[39m replace_context\n\u001b[1;32m    207\u001b[0m \u001b[39mtry\u001b[39;00m:\n\u001b[0;32m--> 208\u001b[0m     \u001b[39mraise\u001b[39;00m exception\n\u001b[1;32m    209\u001b[0m \u001b[39mfinally\u001b[39;00m:\n\u001b[1;32m    210\u001b[0m     \u001b[39m# credit to\u001b[39;00m\n\u001b[1;32m    211\u001b[0m     \u001b[39m# https://cosmicpercolator.com/2016/01/13/exception-leaks-in-python-2-and-3/\u001b[39;00m\n\u001b[1;32m    212\u001b[0m     \u001b[39m# as the __traceback__ object creates a cycle\u001b[39;00m\n\u001b[1;32m    213\u001b[0m     \u001b[39mdel\u001b[39;00m exception, replace_context, from_, with_traceback\n",
      "File \u001b[0;32m~/anaconda3/envs/dev/lib/python3.10/site-packages/sqlalchemy/engine/base.py:3280\u001b[0m, in \u001b[0;36mEngine._wrap_pool_connect\u001b[0;34m(self, fn, connection)\u001b[0m\n\u001b[1;32m   3278\u001b[0m dialect \u001b[39m=\u001b[39m \u001b[39mself\u001b[39m\u001b[39m.\u001b[39mdialect\n\u001b[1;32m   3279\u001b[0m \u001b[39mtry\u001b[39;00m:\n\u001b[0;32m-> 3280\u001b[0m     \u001b[39mreturn\u001b[39;00m fn()\n\u001b[1;32m   3281\u001b[0m \u001b[39mexcept\u001b[39;00m dialect\u001b[39m.\u001b[39mdbapi\u001b[39m.\u001b[39mError \u001b[39mas\u001b[39;00m e:\n\u001b[1;32m   3282\u001b[0m     \u001b[39mif\u001b[39;00m connection \u001b[39mis\u001b[39;00m \u001b[39mNone\u001b[39;00m:\n",
      "File \u001b[0;32m~/anaconda3/envs/dev/lib/python3.10/site-packages/sqlalchemy/pool/base.py:310\u001b[0m, in \u001b[0;36mPool.connect\u001b[0;34m(self)\u001b[0m\n\u001b[1;32m    302\u001b[0m \u001b[39mdef\u001b[39;00m \u001b[39mconnect\u001b[39m(\u001b[39mself\u001b[39m):\n\u001b[1;32m    303\u001b[0m     \u001b[39m\"\"\"Return a DBAPI connection from the pool.\u001b[39;00m\n\u001b[1;32m    304\u001b[0m \n\u001b[1;32m    305\u001b[0m \u001b[39m    The connection is instrumented such that when its\u001b[39;00m\n\u001b[0;32m   (...)\u001b[0m\n\u001b[1;32m    308\u001b[0m \n\u001b[1;32m    309\u001b[0m \u001b[39m    \"\"\"\u001b[39;00m\n\u001b[0;32m--> 310\u001b[0m     \u001b[39mreturn\u001b[39;00m _ConnectionFairy\u001b[39m.\u001b[39;49m_checkout(\u001b[39mself\u001b[39;49m)\n",
      "File \u001b[0;32m~/anaconda3/envs/dev/lib/python3.10/site-packages/sqlalchemy/pool/base.py:868\u001b[0m, in \u001b[0;36m_ConnectionFairy._checkout\u001b[0;34m(cls, pool, threadconns, fairy)\u001b[0m\n\u001b[1;32m    865\u001b[0m \u001b[39m@classmethod\u001b[39m\n\u001b[1;32m    866\u001b[0m \u001b[39mdef\u001b[39;00m \u001b[39m_checkout\u001b[39m(\u001b[39mcls\u001b[39m, pool, threadconns\u001b[39m=\u001b[39m\u001b[39mNone\u001b[39;00m, fairy\u001b[39m=\u001b[39m\u001b[39mNone\u001b[39;00m):\n\u001b[1;32m    867\u001b[0m     \u001b[39mif\u001b[39;00m \u001b[39mnot\u001b[39;00m fairy:\n\u001b[0;32m--> 868\u001b[0m         fairy \u001b[39m=\u001b[39m _ConnectionRecord\u001b[39m.\u001b[39;49mcheckout(pool)\n\u001b[1;32m    870\u001b[0m         fairy\u001b[39m.\u001b[39m_pool \u001b[39m=\u001b[39m pool\n\u001b[1;32m    871\u001b[0m         fairy\u001b[39m.\u001b[39m_counter \u001b[39m=\u001b[39m \u001b[39m0\u001b[39m\n",
      "File \u001b[0;32m~/anaconda3/envs/dev/lib/python3.10/site-packages/sqlalchemy/pool/base.py:476\u001b[0m, in \u001b[0;36m_ConnectionRecord.checkout\u001b[0;34m(cls, pool)\u001b[0m\n\u001b[1;32m    474\u001b[0m \u001b[39m@classmethod\u001b[39m\n\u001b[1;32m    475\u001b[0m \u001b[39mdef\u001b[39;00m \u001b[39mcheckout\u001b[39m(\u001b[39mcls\u001b[39m, pool):\n\u001b[0;32m--> 476\u001b[0m     rec \u001b[39m=\u001b[39m pool\u001b[39m.\u001b[39;49m_do_get()\n\u001b[1;32m    477\u001b[0m     \u001b[39mtry\u001b[39;00m:\n\u001b[1;32m    478\u001b[0m         dbapi_connection \u001b[39m=\u001b[39m rec\u001b[39m.\u001b[39mget_connection()\n",
      "File \u001b[0;32m~/anaconda3/envs/dev/lib/python3.10/site-packages/sqlalchemy/pool/impl.py:145\u001b[0m, in \u001b[0;36mQueuePool._do_get\u001b[0;34m(self)\u001b[0m\n\u001b[1;32m    143\u001b[0m         \u001b[39mreturn\u001b[39;00m \u001b[39mself\u001b[39m\u001b[39m.\u001b[39m_create_connection()\n\u001b[1;32m    144\u001b[0m     \u001b[39mexcept\u001b[39;00m:\n\u001b[0;32m--> 145\u001b[0m         \u001b[39mwith\u001b[39;00m util\u001b[39m.\u001b[39msafe_reraise():\n\u001b[1;32m    146\u001b[0m             \u001b[39mself\u001b[39m\u001b[39m.\u001b[39m_dec_overflow()\n\u001b[1;32m    147\u001b[0m \u001b[39melse\u001b[39;00m:\n",
      "File \u001b[0;32m~/anaconda3/envs/dev/lib/python3.10/site-packages/sqlalchemy/util/langhelpers.py:70\u001b[0m, in \u001b[0;36msafe_reraise.__exit__\u001b[0;34m(self, type_, value, traceback)\u001b[0m\n\u001b[1;32m     68\u001b[0m     \u001b[39mself\u001b[39m\u001b[39m.\u001b[39m_exc_info \u001b[39m=\u001b[39m \u001b[39mNone\u001b[39;00m  \u001b[39m# remove potential circular references\u001b[39;00m\n\u001b[1;32m     69\u001b[0m     \u001b[39mif\u001b[39;00m \u001b[39mnot\u001b[39;00m \u001b[39mself\u001b[39m\u001b[39m.\u001b[39mwarn_only:\n\u001b[0;32m---> 70\u001b[0m         compat\u001b[39m.\u001b[39;49mraise_(\n\u001b[1;32m     71\u001b[0m             exc_value,\n\u001b[1;32m     72\u001b[0m             with_traceback\u001b[39m=\u001b[39;49mexc_tb,\n\u001b[1;32m     73\u001b[0m         )\n\u001b[1;32m     74\u001b[0m \u001b[39melse\u001b[39;00m:\n\u001b[1;32m     75\u001b[0m     \u001b[39mif\u001b[39;00m \u001b[39mnot\u001b[39;00m compat\u001b[39m.\u001b[39mpy3k \u001b[39mand\u001b[39;00m \u001b[39mself\u001b[39m\u001b[39m.\u001b[39m_exc_info \u001b[39mand\u001b[39;00m \u001b[39mself\u001b[39m\u001b[39m.\u001b[39m_exc_info[\u001b[39m1\u001b[39m]:\n\u001b[1;32m     76\u001b[0m         \u001b[39m# emulate Py3K's behavior of telling us when an exception\u001b[39;00m\n\u001b[1;32m     77\u001b[0m         \u001b[39m# occurs in an exception handler.\u001b[39;00m\n",
      "File \u001b[0;32m~/anaconda3/envs/dev/lib/python3.10/site-packages/sqlalchemy/util/compat.py:208\u001b[0m, in \u001b[0;36mraise_\u001b[0;34m(***failed resolving arguments***)\u001b[0m\n\u001b[1;32m    205\u001b[0m     exception\u001b[39m.\u001b[39m__cause__ \u001b[39m=\u001b[39m replace_context\n\u001b[1;32m    207\u001b[0m \u001b[39mtry\u001b[39;00m:\n\u001b[0;32m--> 208\u001b[0m     \u001b[39mraise\u001b[39;00m exception\n\u001b[1;32m    209\u001b[0m \u001b[39mfinally\u001b[39;00m:\n\u001b[1;32m    210\u001b[0m     \u001b[39m# credit to\u001b[39;00m\n\u001b[1;32m    211\u001b[0m     \u001b[39m# https://cosmicpercolator.com/2016/01/13/exception-leaks-in-python-2-and-3/\u001b[39;00m\n\u001b[1;32m    212\u001b[0m     \u001b[39m# as the __traceback__ object creates a cycle\u001b[39;00m\n\u001b[1;32m    213\u001b[0m     \u001b[39mdel\u001b[39;00m exception, replace_context, from_, with_traceback\n",
      "File \u001b[0;32m~/anaconda3/envs/dev/lib/python3.10/site-packages/sqlalchemy/pool/impl.py:143\u001b[0m, in \u001b[0;36mQueuePool._do_get\u001b[0;34m(self)\u001b[0m\n\u001b[1;32m    141\u001b[0m \u001b[39mif\u001b[39;00m \u001b[39mself\u001b[39m\u001b[39m.\u001b[39m_inc_overflow():\n\u001b[1;32m    142\u001b[0m     \u001b[39mtry\u001b[39;00m:\n\u001b[0;32m--> 143\u001b[0m         \u001b[39mreturn\u001b[39;00m \u001b[39mself\u001b[39;49m\u001b[39m.\u001b[39;49m_create_connection()\n\u001b[1;32m    144\u001b[0m     \u001b[39mexcept\u001b[39;00m:\n\u001b[1;32m    145\u001b[0m         \u001b[39mwith\u001b[39;00m util\u001b[39m.\u001b[39msafe_reraise():\n",
      "File \u001b[0;32m~/anaconda3/envs/dev/lib/python3.10/site-packages/sqlalchemy/pool/base.py:256\u001b[0m, in \u001b[0;36mPool._create_connection\u001b[0;34m(self)\u001b[0m\n\u001b[1;32m    253\u001b[0m \u001b[39mdef\u001b[39;00m \u001b[39m_create_connection\u001b[39m(\u001b[39mself\u001b[39m):\n\u001b[1;32m    254\u001b[0m     \u001b[39m\"\"\"Called by subclasses to create a new ConnectionRecord.\"\"\"\u001b[39;00m\n\u001b[0;32m--> 256\u001b[0m     \u001b[39mreturn\u001b[39;00m _ConnectionRecord(\u001b[39mself\u001b[39;49m)\n",
      "File \u001b[0;32m~/anaconda3/envs/dev/lib/python3.10/site-packages/sqlalchemy/pool/base.py:371\u001b[0m, in \u001b[0;36m_ConnectionRecord.__init__\u001b[0;34m(self, pool, connect)\u001b[0m\n\u001b[1;32m    369\u001b[0m \u001b[39mself\u001b[39m\u001b[39m.\u001b[39m__pool \u001b[39m=\u001b[39m pool\n\u001b[1;32m    370\u001b[0m \u001b[39mif\u001b[39;00m connect:\n\u001b[0;32m--> 371\u001b[0m     \u001b[39mself\u001b[39;49m\u001b[39m.\u001b[39;49m__connect()\n\u001b[1;32m    372\u001b[0m \u001b[39mself\u001b[39m\u001b[39m.\u001b[39mfinalize_callback \u001b[39m=\u001b[39m deque()\n",
      "File \u001b[0;32m~/anaconda3/envs/dev/lib/python3.10/site-packages/sqlalchemy/pool/base.py:665\u001b[0m, in \u001b[0;36m_ConnectionRecord.__connect\u001b[0;34m(self)\u001b[0m\n\u001b[1;32m    663\u001b[0m     \u001b[39mself\u001b[39m\u001b[39m.\u001b[39mfresh \u001b[39m=\u001b[39m \u001b[39mTrue\u001b[39;00m\n\u001b[1;32m    664\u001b[0m \u001b[39mexcept\u001b[39;00m \u001b[39mException\u001b[39;00m \u001b[39mas\u001b[39;00m e:\n\u001b[0;32m--> 665\u001b[0m     \u001b[39mwith\u001b[39;00m util\u001b[39m.\u001b[39msafe_reraise():\n\u001b[1;32m    666\u001b[0m         pool\u001b[39m.\u001b[39mlogger\u001b[39m.\u001b[39mdebug(\u001b[39m\"\u001b[39m\u001b[39mError on connect(): \u001b[39m\u001b[39m%s\u001b[39;00m\u001b[39m\"\u001b[39m, e)\n\u001b[1;32m    667\u001b[0m \u001b[39melse\u001b[39;00m:\n\u001b[1;32m    668\u001b[0m     \u001b[39m# in SQLAlchemy 1.4 the first_connect event is not used by\u001b[39;00m\n\u001b[1;32m    669\u001b[0m     \u001b[39m# the engine, so this will usually not be set\u001b[39;00m\n",
      "File \u001b[0;32m~/anaconda3/envs/dev/lib/python3.10/site-packages/sqlalchemy/util/langhelpers.py:70\u001b[0m, in \u001b[0;36msafe_reraise.__exit__\u001b[0;34m(self, type_, value, traceback)\u001b[0m\n\u001b[1;32m     68\u001b[0m     \u001b[39mself\u001b[39m\u001b[39m.\u001b[39m_exc_info \u001b[39m=\u001b[39m \u001b[39mNone\u001b[39;00m  \u001b[39m# remove potential circular references\u001b[39;00m\n\u001b[1;32m     69\u001b[0m     \u001b[39mif\u001b[39;00m \u001b[39mnot\u001b[39;00m \u001b[39mself\u001b[39m\u001b[39m.\u001b[39mwarn_only:\n\u001b[0;32m---> 70\u001b[0m         compat\u001b[39m.\u001b[39;49mraise_(\n\u001b[1;32m     71\u001b[0m             exc_value,\n\u001b[1;32m     72\u001b[0m             with_traceback\u001b[39m=\u001b[39;49mexc_tb,\n\u001b[1;32m     73\u001b[0m         )\n\u001b[1;32m     74\u001b[0m \u001b[39melse\u001b[39;00m:\n\u001b[1;32m     75\u001b[0m     \u001b[39mif\u001b[39;00m \u001b[39mnot\u001b[39;00m compat\u001b[39m.\u001b[39mpy3k \u001b[39mand\u001b[39;00m \u001b[39mself\u001b[39m\u001b[39m.\u001b[39m_exc_info \u001b[39mand\u001b[39;00m \u001b[39mself\u001b[39m\u001b[39m.\u001b[39m_exc_info[\u001b[39m1\u001b[39m]:\n\u001b[1;32m     76\u001b[0m         \u001b[39m# emulate Py3K's behavior of telling us when an exception\u001b[39;00m\n\u001b[1;32m     77\u001b[0m         \u001b[39m# occurs in an exception handler.\u001b[39;00m\n",
      "File \u001b[0;32m~/anaconda3/envs/dev/lib/python3.10/site-packages/sqlalchemy/util/compat.py:208\u001b[0m, in \u001b[0;36mraise_\u001b[0;34m(***failed resolving arguments***)\u001b[0m\n\u001b[1;32m    205\u001b[0m     exception\u001b[39m.\u001b[39m__cause__ \u001b[39m=\u001b[39m replace_context\n\u001b[1;32m    207\u001b[0m \u001b[39mtry\u001b[39;00m:\n\u001b[0;32m--> 208\u001b[0m     \u001b[39mraise\u001b[39;00m exception\n\u001b[1;32m    209\u001b[0m \u001b[39mfinally\u001b[39;00m:\n\u001b[1;32m    210\u001b[0m     \u001b[39m# credit to\u001b[39;00m\n\u001b[1;32m    211\u001b[0m     \u001b[39m# https://cosmicpercolator.com/2016/01/13/exception-leaks-in-python-2-and-3/\u001b[39;00m\n\u001b[1;32m    212\u001b[0m     \u001b[39m# as the __traceback__ object creates a cycle\u001b[39;00m\n\u001b[1;32m    213\u001b[0m     \u001b[39mdel\u001b[39;00m exception, replace_context, from_, with_traceback\n",
      "File \u001b[0;32m~/anaconda3/envs/dev/lib/python3.10/site-packages/sqlalchemy/pool/base.py:661\u001b[0m, in \u001b[0;36m_ConnectionRecord.__connect\u001b[0;34m(self)\u001b[0m\n\u001b[1;32m    659\u001b[0m \u001b[39mtry\u001b[39;00m:\n\u001b[1;32m    660\u001b[0m     \u001b[39mself\u001b[39m\u001b[39m.\u001b[39mstarttime \u001b[39m=\u001b[39m time\u001b[39m.\u001b[39mtime()\n\u001b[0;32m--> 661\u001b[0m     \u001b[39mself\u001b[39m\u001b[39m.\u001b[39mdbapi_connection \u001b[39m=\u001b[39m connection \u001b[39m=\u001b[39m pool\u001b[39m.\u001b[39;49m_invoke_creator(\u001b[39mself\u001b[39;49m)\n\u001b[1;32m    662\u001b[0m     pool\u001b[39m.\u001b[39mlogger\u001b[39m.\u001b[39mdebug(\u001b[39m\"\u001b[39m\u001b[39mCreated new connection \u001b[39m\u001b[39m%r\u001b[39;00m\u001b[39m\"\u001b[39m, connection)\n\u001b[1;32m    663\u001b[0m     \u001b[39mself\u001b[39m\u001b[39m.\u001b[39mfresh \u001b[39m=\u001b[39m \u001b[39mTrue\u001b[39;00m\n",
      "File \u001b[0;32m~/anaconda3/envs/dev/lib/python3.10/site-packages/sqlalchemy/engine/create.py:590\u001b[0m, in \u001b[0;36mcreate_engine.<locals>.connect\u001b[0;34m(connection_record)\u001b[0m\n\u001b[1;32m    588\u001b[0m         \u001b[39mif\u001b[39;00m connection \u001b[39mis\u001b[39;00m \u001b[39mnot\u001b[39;00m \u001b[39mNone\u001b[39;00m:\n\u001b[1;32m    589\u001b[0m             \u001b[39mreturn\u001b[39;00m connection\n\u001b[0;32m--> 590\u001b[0m \u001b[39mreturn\u001b[39;00m dialect\u001b[39m.\u001b[39;49mconnect(\u001b[39m*\u001b[39;49mcargs, \u001b[39m*\u001b[39;49m\u001b[39m*\u001b[39;49mcparams)\n",
      "File \u001b[0;32m~/anaconda3/envs/dev/lib/python3.10/site-packages/sqlalchemy/engine/default.py:597\u001b[0m, in \u001b[0;36mDefaultDialect.connect\u001b[0;34m(self, *cargs, **cparams)\u001b[0m\n\u001b[1;32m    595\u001b[0m \u001b[39mdef\u001b[39;00m \u001b[39mconnect\u001b[39m(\u001b[39mself\u001b[39m, \u001b[39m*\u001b[39mcargs, \u001b[39m*\u001b[39m\u001b[39m*\u001b[39mcparams):\n\u001b[1;32m    596\u001b[0m     \u001b[39m# inherits the docstring from interfaces.Dialect.connect\u001b[39;00m\n\u001b[0;32m--> 597\u001b[0m     \u001b[39mreturn\u001b[39;00m \u001b[39mself\u001b[39;49m\u001b[39m.\u001b[39;49mdbapi\u001b[39m.\u001b[39;49mconnect(\u001b[39m*\u001b[39;49mcargs, \u001b[39m*\u001b[39;49m\u001b[39m*\u001b[39;49mcparams)\n",
      "File \u001b[0;32m~/anaconda3/envs/dev/lib/python3.10/site-packages/psycopg2/__init__.py:122\u001b[0m, in \u001b[0;36mconnect\u001b[0;34m(dsn, connection_factory, cursor_factory, **kwargs)\u001b[0m\n\u001b[1;32m    119\u001b[0m     kwasync[\u001b[39m'\u001b[39m\u001b[39masync_\u001b[39m\u001b[39m'\u001b[39m] \u001b[39m=\u001b[39m kwargs\u001b[39m.\u001b[39mpop(\u001b[39m'\u001b[39m\u001b[39masync_\u001b[39m\u001b[39m'\u001b[39m)\n\u001b[1;32m    121\u001b[0m dsn \u001b[39m=\u001b[39m _ext\u001b[39m.\u001b[39mmake_dsn(dsn, \u001b[39m*\u001b[39m\u001b[39m*\u001b[39mkwargs)\n\u001b[0;32m--> 122\u001b[0m conn \u001b[39m=\u001b[39m _connect(dsn, connection_factory\u001b[39m=\u001b[39;49mconnection_factory, \u001b[39m*\u001b[39;49m\u001b[39m*\u001b[39;49mkwasync)\n\u001b[1;32m    123\u001b[0m \u001b[39mif\u001b[39;00m cursor_factory \u001b[39mis\u001b[39;00m \u001b[39mnot\u001b[39;00m \u001b[39mNone\u001b[39;00m:\n\u001b[1;32m    124\u001b[0m     conn\u001b[39m.\u001b[39mcursor_factory \u001b[39m=\u001b[39m cursor_factory\n",
      "\u001b[0;31mOperationalError\u001b[0m: (psycopg2.OperationalError) FATAL:  database \"test_db\" does not exist\n\n(Background on this error at: https://sqlalche.me/e/14/e3q8)"
     ]
    }
   ],
   "source": [
    "# Reflect Database into ORM classes\n",
    "Base = automap_base()\n",
    "Base.prepare(autoload_with=engine)\n",
    "Base.classes.keys()"
   ]
  }
 ],
 "metadata": {
  "kernelspec": {
   "display_name": "dev",
   "language": "python",
   "name": "python3"
  },
  "language_info": {
   "codemirror_mode": {
    "name": "ipython",
    "version": 3
   },
   "file_extension": ".py",
   "mimetype": "text/x-python",
   "name": "python",
   "nbconvert_exporter": "python",
   "pygments_lexer": "ipython3",
   "version": "3.10.11"
  },
  "orig_nbformat": 4
 },
 "nbformat": 4,
 "nbformat_minor": 2
}
